Workbook

Sheet Sheet1
B2: V_n | C2: 115 | D2: mph | E2: K_z (0-15) | F2: 0.85
B3: K_zt | C3: 1 | E3: K_z (15-20) | F3: 0.9
B4: K_d | C4: 1 | E4: K_z(25.656) | F4: =(C12-25)/(5)*(H4-G4)+G4 -> 0.94525 | G4: 0.94 | H4: 0.98
B5: K_e | C5: 1 | E5: L | F5: 48 | G5: ft | H5: *Could try 48'-8"
B6: G | C6: 0.85 | E6: B | F6: 40 | G6: ft | H6: *Could try 41'-1 3/4"
B7: GC_pi | C7: 0.18
C8: -0.18
A11: Q1 | B11: Structure Height | C11: 20 | D11: ft
A12: Q2 | B12: Mean Roof Height | C12: =C11+(11+(3+3/4)/12)/2 -> 25.65625 | D12: ft | E12: *Could try 10'-6 5/8" | I12: Leeward Wall Interpolation
A13: Q3 | B13: q_z (0-15) | C13: =0.00256*F2*C3*C4*C5*C2^2 -> 28.7776 | D13: psf | I13: 1 | J13: 2
A14: Q4 | B14: q_z (15-20) | C14: =0.00256*F3*C3*C4*C5*C2^2 -> 30.4704 | D14: psf | I14: -0.5 | J14: -0.3
A15: Q5 | B15: q_h | C15: =0.00256*F4*C3*C4*C5*C2^2 -> 32.002384 | D15: psf
A16: Q6 | B16: L/B | C16: =F5/F6 -> 1.2 | D16: ft | J16: Windward Roof Interpolation
A17: Q7 | B17: H/L | C17: =C11/F5 -> 0.41666667 | D17: ft | I17: .@25 | J17: 0.25 | K17: 0.5
A18: Q8 | B18: Angle | C18: =ATAN((C12-C11)*2/(F5/2))*180/PI() -> 25.237041 | D18: degrees | E18: *Revit says 22.62 | I18: =C17 -> 0.41666667 | J18: -0.2 | K18: -0.3 | L18: 25 | M18: =(I18-J17)/(K17-J17)*(K18-J18)+J18 -> -0.26666667
A19: Q9 | B19: Cp Windward | C19: 0.8 | E19: *Use with q_z
A20: Q10 | B20: Cp Leeward wall | C20: =(C16-I13)/(J13-I13)*(J14-I14)+I14 -> -0.46 | E20: *Use with q_h | I20: .@30 | J20: 0.25 | K20: 0.5
A21: Q11 | B21: Cp Side wall | C21: -0.7 | E21: *Use with q_h | I21: =I18 -> 0.41666667 | J21: -0.2 | K21: -0.2 | L21: 30 | M21: =(I21-J20)/(K20-J20)*(K21-J21)+J21 -> -0.2
A22: Q12 | B22: Cp Windward Rooft | C22: =(C18-L18)/(L21-L18)*(M21-M18)+M18 -> -0.26350612 | E22: *Use with q_h
A23: Q13 | B23: Cp Leward Roof | C23: -0.6 | E23: *Use with q_h
A24: Q14 | B24: qh(Gcpi) | C24: =C15*C7 -> 5.7604291 | D24: =C15*C8 -> -5.7604291
A25: Q15 | B25: Windward wall (0-15) | C25: =C13*C6*(C19)-C24 -> 13.808339 | D25: =C13*C6*(C19)-D24 -> 25.329197 | E25: psf
A26: Q16 | B26: Windward wall (15-20) | C26: =C14*C6*(C19)-C24 -> 14.959443 | D26: =C14*C6*(C19)-D24 -> 26.480301 | E26: psf
A27: Q17 | B27: Leeward wall | C27: =C15*C8*(C20)-C24 -> -3.1106317 | D27: =C15*C8*(C20)-D24 -> 8.4102265 | E27: psf
A28: Q18 | B28: Sidewall | C28: =C15*C8*(C21)-C24 -> -1.7281287 | D28: =C15*C8*(C21)-D24 -> 9.7927295 | E28: psf
A29: Q19 | B29: Windward Roof | C29: =C15*C8*(C22)-C24 -> -4.2425208 | D29: =C15*C8*(C22)-D24 -> 7.2783374 | E29: psf
A30: Q20 | B30: Leeward Roof | C30: =C15*C8*(C23)-C24 -> -2.3041716 | D30: =C15*C8*(C23)-D24 -> 9.2166866 | E30: psf
A31: Q21 | C31: T
A32: Q22 | B32: Trib Center | C32: =F6/2 -> 20 | D32: ft
A33: Q23 | B33: Windward loads (0-15) | C33: =$F$6/2*C25 -> 276.16678 | D33: =$F$6/2*D25 -> 506.58394 | E33: plf
A34: Q24 | B34: Windward loads (15-20) | C34: =$F$6/2*C26 -> 299.18886 | D34: =F6/2*D26 -> 529.60602 | E34: plf
A35: Q25 | B35: Leeward loads | C35: =$F$6/2*C27 -> -62.212634 | D35: =F6/2*D27 -> 168.20453 | E35: plf
A36: Q26 | B36: Windward Truss Loads | C36: =$F$6/2*C28 -> -34.562575 | D36: =D29*F6/2 -> 145.56675 | E36: plf
A37: Q27 | B37: Leeward Truss loads | C37: =$F$6/2*C29 -> -84.850416 | D37: =D30*F6/2 -> 184.33373 | E37: plf
A38: Q28 | C38: Do when ansers are verified
A39: Q29 | C39: Do when ansers are verified
A40: Q30 | B40: Factor | C40: 0.5
A41: Q31 | C41: T
A42: Q32 | B42: Node 0 1 Trip | C42: =Proj1!C9/(Sheet1!F6/2) -> 4.2882487 | D42: ft
A43: Q33 | B43: Node 8 9 Trip | C43: =Proj1!C10/(Sheet1!$F$6/2) -> 8.5764974 | D43: ft
...

Sheet Proj1
B3: Truss Weight | C3: 19 | D3: plf | E3: Live load | F3: 650 | G3: Each node | I3: Bo and B11 | J3: =8+(6+235/256)/12 -> 8.5764974 | K3: ft
B4: Purlin weight | C4: 10 | D4: plf | E4: Snow Load | F4: 26.5 | G4: psf | I4: B1 and B10 | J4: =8+(6+235/256)/12 -> 8.5764974 | K4: ft
B5: Plywood | C5: 2.4 | D5: psf | I5: B2 and B9 | J5: =8+(10+43/256)/12 -> 8.8473307 | K5: ft
B6: Shingles | C6: 2.7 | D6: psf | I6: B3 and B8 | J6: =7+11/12 -> 7.9166667 | K6: ft
I7: B4 and B7 | J7: =7+11/12 -> 7.9166667 | K7: ft
B8: Trib Areas | E8: Snow Trib areas | I8: B5 and B6 | J8: =8+2/12 -> 8.1666667 | K8: ft
B9: Node 0 and 1 | C9: =J14/2*J3/2 -> 85.764974 | E9: Node 0 and 1 | F9: =J14/2*J6/2 -> 79.166667 | I9: B19 and B20 | J9: =3+(3+149/256)/12 -> 3.2985026 | K9: ft
B10: Nodes 8 and 9 | C10: =J14/2*(J3/2+J4/2) -> 171.52995 | E10: Nodes 8 and 9 | F10: =J14/2*(J6/2+J7/2) -> 158.33333 | I10: B15 and B17 | J10: =8+(6+235/256)/12 -> 8.5764974 | K10: ft
B11: Nodes 5 and 7 | C11: =J14/2*(J4/2+J5/2) -> 174.23828 | E11: Nodes 5 and 7 | F11: =J14/2*(J7/2+J8/2) -> 160.83333 | I11: B13 and B14 | J11: =6+7.1/12 -> 6.5916667 | K11: ft
B12: Node 2 | C12: =J14/2*J5 -> 176.94661 | E12: Node 2 | F12: =J14/2*(J8) -> 163.33333 | I12: B16 and B18 | J12: =12+10.9/12 -> 12.908333 | K12: ft
I13: B12 | J13: 10 | K13: ft
B14: Weigth From Roof | E14: Weight From snow | I14: Purlin | J14: 40 | K14: ft
B15: Node 0 and 1 | C15: =C9*($C$5+$C$6) -> 437.40137 | E15: Node 0 and 1 | F15: =F9*$F$4 -> 2097.9167 | I15: Area | J15: =J14*(J3+J4+J5)*2*2 -> 4160.0521 | K15: ft^2
B16: Nodes 8 and 9 | C16: =C10*($C$5+$C$6) -> 874.80273 | E16: Nodes 8 and 9 | F16: =F10*$F$4 -> 4195.8333
B17: Nodes 5 and 7 | C17: =C11*($C$5+$C$6) -> 888.61523 | E17: Nodes 5 and 7 | F17: =F11*$F$4 -> 4262.0833
B18: Node 2 | C18: =C12*($C$5+$C$6) -> 902.42773 | E18: Node 2 | F18: =F12*$F$4 -> 4328.3333
B20: Weigth From Purlins | E20: COnstruction weight
B21: Node 0 and 1 | C21: =$J$14/2*$C$4 -> 200 | E21: Node 0 and 1 | F21: 650
B22: Nodes 8 and 9 | C22: =$J$14/2*$C$4 -> 200 | E22: Nodes 8 and 9 | F22: 650
B23: Nodes 5 and 7 | C23: =$J$14/2*$C$4 -> 200 | E23: Nodes 5 and 7 | F23: 650
B24: Node 2 | C24: =$J$14/2*$C$4*2 -> 400 | E24: Node 2 | F24: 650
B26: Total Dead Load | E26: Dead snow live
B27: Node 0 and 1 | C27: =C21+C15 -> 637.40137 | E27: Dead | F27: 1.2
B28: Nodes 8 and 9 | C28: =C22+C16 -> 1074.8027 | E28: Live | F28: 1.6
B29: Nodes 5 and 7 | C29: =C23+C17 -> 1088.6152 | E29: Snow | F29: 0.5
B30: Node 2 | C30: =C24+C18 -> 1302.4277
B32: Dead Only Load Combo | C32: 1.4 | E32: Totals
B33: Node 0 and 1 | C33: =$C$32*C27 -> 892.36191 | E33: Node 0 and 1 | F33: =C27*$F$27+F15*$F$29+F21*$F$28 -> 2853.84
B34: Nodes 8 and 9 | C34: =$C$32*C28 -> 1504.7238 | E34: Nodes 8 and 9 | F34: =C28*$F$27+F16*$F$29+F22*$F$28 -> 4427.6799
B35: Nodes 5 and 7 | C35: =$C$32*C29 -> 1524.0613 | E35: Nodes 5 and 7 | F35: =C29*$F$27+F17*$F$29+F23*$F$28 -> 4477.3799
B36: Node 2 | C36: =$C$32*C30 -> 1823.3988 | E36: Node 2 | F36: =C30*$F$27+F18*$F$29+F24*$F$28 -> 4767.0799
B38: Rx1 | C38: 0
B39: Ry1 | C39: =(F33*2+F34*2+F35*2+F36)/2 -> 14142.44
B40: Ry2 | C40: =C39 -> 14142.44
B42: B0 | C42: =(J3/J9)*(F33-C39) -> -29351.697
B43: B3 | C43: =-(J6/J3)*C42 -> 27093.531
B44: B4 | C44: =C43 -> 27093.531
B45: B19 | C45: 0
B46: B15 | C46: =(((J11-J9)*C42*J6)/(J4*J3)-(J7/J4)*(C42*(J9/J3)+F34))/E46 -> -5737.1363 | D46: d | E46: =((J11-J9)*J7)/(J4*J10)+(J9*J7)/(J10*J4) -> 0.70944328
B47: B1 | C47: =((C42*(J9/J3)+F34)*(J7/J10)+(C42*J6*J9)/(J3*J10))/E46 -> -23614.56
...
